Workbook

Sheet الملخص
A1: دراسة تسعير يولياس — الملخص (استخدام عادي)
A2: كل الأرقام بتتحسب من شيت «المدخلات». الخانات الصفرا هناك هي قراراتك والأرقام اللي محتاجة تأكيد.
B4: Pro — قبل المزود | C4: Pro — مع المزود | D4: Growth — قبل المزود | E4: Growth — مع المزود
A5: السعر | B5: ='اقتصاديات الباقة'!B5 | C5: ='اقتصاديات الباقة'!C5 | D5: ='اقتصاديات الباقة'!D5 | E5: ='اقتصاديات الباقة'!E5
A6: العملاء المحتملين في الشهر | B6: ='اقتصاديات الباقة'!B6 | C6: ='اقتصاديات الباقة'!C6 | D6: ='اقتصاديات الباقة'!D6 | E6: ='اقتصاديات الباقة'!E6
A7: صنّاع القرار في الشهر | B7: ='المدخلات'!$B$37 | C7: ='المدخلات'!$B$37 | D7: ='المدخلات'!$B$38 | E7: ='المدخلات'!$B$38
A8: قراءة الموقع (Enrichment) | B8: ='اقتصاديات الباقة'!B6 | C8: ='اقتصاديات الباقة'!C6 | D8: ='اقتصاديات الباقة'!D6 | E8: ='اقتصاديات الباقة'!E6
A9: رسائل Yolias AI في الشهر (عادي) | B9: ='تكلفة AI'!C10 | C9: ='تكلفة AI'!C10 | D9: ='تكلفة AI'!C12 | E9: ='تكلفة AI'!C12
A10: رسائل تواصل مكتوبة في الشهر (عادي) | B10: ='تكلفة AI'!D10 | C10: ='تكلفة AI'!D10 | D10: ='تكلفة AI'!D12 | E10: ='تكلفة AI'!D12
A11: إجمالي التكلفة — عادي | B11: ='اقتصاديات الباقة'!B13 | C11: ='اقتصاديات الباقة'!C13 | D11: ='اقتصاديات الباقة'!D13 | E11: ='اقتصاديات الباقة'!E13
A12: إجمالي الربح — عادي | B12: ='اقتصاديات الباقة'!B14 | C12: ='اقتصاديات الباقة'!C14 | D12: ='اقتصاديات الباقة'!D14 | E12: ='اقتصاديات الباقة'!E14
A13: الهامش — عادي | B13: ='اقتصاديات الباقة'!B15 | C13: ='اقتصاديات الباقة'!C15 | D13: ='اقتصاديات الباقة'!D15 | E13: ='اقتصاديات الباقة'!E15
A14: إجمالي التكلفة — أقصى استخدام | B14: ='اقتصاديات الباقة'!B28 | C14: ='اقتصاديات الباقة'!C28 | D14: ='اقتصاديات الباقة'!D28 | E14: ='اقتصاديات الباقة'!E28
A15: الهامش — أقصى استخدام | B15: ='اقتصاديات الباقة'!B30 | C15: ='اقتصاديات الباقة'!C30 | D15: ='اقتصاديات الباقة'!D30 | E15: ='اقتصاديات الباقة'!E30
A16: إجمالي التكلفة — أسوأ حالة (2027) | B16: ='اقتصاديات الباقة'!B43 | C16: ='اقتصاديات الباقة'!C43 | D16: ='اقتصاديات الباقة'!D43 | E16: ='اقتصاديات الباقة'!E43
A17: الهامش — أسوأ حالة (2027) | B17: ='اقتصاديات الباقة'!B45 | C17: ='اقتصاديات الباقة'!C45 | D17: ='اقتصاديات الباقة'!D45 | E17: ='اقتصاديات الباقة'!E45
A18: سعر بيع الـ Prospect | B18: ='لكل Prospect'!B4 | C18: ='لكل Prospect'!C4 | D18: ='لكل Prospect'!D4 | E18: ='لكل Prospect'!E4
A19: تكلفة الـ Prospect | B19: ='لكل Prospect'!B10 | C19: ='لكل Prospect'!C10 | D19: ='لكل Prospect'!D10 | E19: ='لكل Prospect'!E10
A20: ربحك في الـ Prospect | B20: ='لكل Prospect'!B11 | C20: ='لكل Prospect'!C11 | D20: ='لكل Prospect'!D11 | E20: ='لكل Prospect'!E11
A22: التكلفة الثابتة الشهرية
B23: 10 | C23: 50 | D23: 100 | E23: 500 | F23: 1,000
A24: التكلفة الثابتة | B24: ='التكلفة الثابتة'!B14 | C24: ='التكلفة الثابتة'!C14 | D24: ='التكلفة الثابتة'!D14 | E24: ='التكلفة الثابتة'!E14 | F24: ='التكلفة الثابتة'!F14
A25: الإيرادات | B25: ='التكلفة الثابتة'!B26 | C25: ='التكلفة الثابتة'!C26 | D25: ='التكلفة الثابتة'!D26 | E25: ='التكلفة الثابتة'!E26 | F25: ='التكلفة الثابتة'!F26
A26: الربح — قبل المزود | B26: ='التكلفة الثابتة'!B32 | C26: ='التكلفة الثابتة'!C32 | D26: ='التكلفة الثابتة'!D32 | E26: ='التكلفة الثابتة'!E32 | F26: ='التكلفة الثابتة'!F32
A27: الهامش — قبل المزود | B27: ='التكلفة الثابتة'!B33 | C27: ='التكلفة الثابتة'!C33 | D27: ='التكلفة الثابتة'!D33 | E27: ='التكلفة الثابتة'!E33 | F27: ='التكلفة الثابتة'!F33
A28: الربح — مع المزود | B28: ='التكلفة الثابتة'!B34 | C28: ='التكلفة الثابتة'!C34 | D28: ='التكلفة الثابتة'!D34 | E28: ='التكلفة الثابتة'!E34 | F28: ='التكلفة الثابتة'!F34
A29: الهامش — مع المزود | B29: ='التكلفة الثابتة'!B35 | C29: ='التكلفة الثابتة'!C35 | D29: ='التكلفة الثابتة'!D35 | E29: ='التكلفة الثابتة'!E35 | F29: ='التكلفة الثابتة'!F35
A31: ملاحظات مهمة:
A32: 1. مفيش مزود بيانات مربوط في الكود دلوقتي، فالبحث في الإنتاج بيرجّع صفر نتائج. عمود «قبل المزود» بيوضح تكلفة التشغيل، مش إيراد ممكن يتحقق النهارده.
A33: 2. Google Places اترفض لأن شروطه بتسمح بتخزين place_id بس، ويولياس بيحفظ النتائج وبيصدّرها CSV.
A34: 3. «مع المزود» محسوب بسعر 0.01$ للـ Prospect كمثال بس. حط سعر المزود الحقيقي في المدخلات.
A35: 4. Gemini سعره بيتضاعف من 2027-01-01 (اختيار الأسعار في المدخلات).
A36: 5. Resend Free بيوقف عند 100 إيميل في اليوم، وتسجيل الدخول بيعتمد عليه. شوف «التكلفة الثابتة» ← Resend.
A37: 6. توكنز AI متوسطات من التجارب المحلية. بعد الإطلاق نستبدلها بالأرقام الحقيقية من intel.llm_calls.

Sheet المدخلات
A1: المدخلات والافتراضات — كل رقم في الدراسة جاي من هنا
A2: الأزرق = رقم مُدخل. الأصفر = قرارك أو رقم محتاج تأكيد أو سعر المزود. غيّر الخانات دي بس، وباقي الشيت هيتحسب لوحده.
A3: البند | B3: القيمة | C3: الوحدة | D3: المصدر / ملاحظة
A4: الباقات
A5: سعر Pro | B5: 50 | C5: $ / شهر | D5: منك (قرار مبدئي)
A6: سعر Growth | B6: 100 | C6: $ / شهر | D6: منك (قرار مبدئي)
A7: الدفع — Paymob
A8: عمولة Paymob | B8: 0.0298 | C8: % من المبلغ | D8: منك 2026-10-07
A9: رسوم ثابتة لكل عملية | B9: 0 | C9: $ / عملية | D9: محتاج تأكيد من عقد Paymob (لو مفيش تفضل 0)
A10: ضريبة على العمولة | B10: 0 | C10: % من العمولة | D10: محتاج تأكيد: لو فيه 14% ضريبة قيمة مضافة على العمولة اكتب 14%
A11: Gemini 3.8 Flash — الموديل الوحيد المستخدم في الإنتاج
A12: سعر Input (السعر الحالي) | B12: 0.75 | C12: $ / مليون توكن | D12: سعر Google المعلن لحد 2026-12-31 (بحث ويب، راجعه على ai.google.dev/pricing)
A13: سعر Output (السعر الحالي) | B13: 3.75 | C13: $ / مليون توكن | D13: نفس المصدر
A14: سعر Input من 2027-01-01 | B14: 1.5 | C14: $ / مليون توكن | D14: نفس المصدر (السعر العادي = ضعف السعر الحالي)
A15: سعر Output من 2027-01-01 | B15: 7.5 | C15: $ / مليون توكن | D15: نفس المصدر
A16: الأسعار المستخدمة في الحساب (1 = الحالية، 2 = 2027) | B16: 1 | C16: اختيار | D16: غيّرها لـ 2 عشان تشوف الهامش بعد زيادة سعر Gemini
A17: توكنز كل عملية (متوسط من سجل الاستدعاءات intel.llm_calls على الداتابيز المحلية)
A18: تحليل طلب البحث — Input | B18: 393 | C18: توكن | D18: متوسط 4 استدعاءات (icp.parse)
A19: تحليل طلب البحث — Output | B19: 791 | C19: توكن | D19: نفس المصدر
A20: رسالة في Yolias AI — Input | B20: 5984 | C20: توكن | D20: متوسط 30 استدعاء (agent)
A21: رسالة في Yolias AI — Output | B21: 403 | C21: توكن | D21: نفس المصدر
A22: كتابة إيميل / رسالة تواصل — Input | B22: 382 | C22: توكن | D22: متوسط 43 استدعاء (write)
A23: كتابة إيميل / رسالة تواصل — Output | B23: 528 | C23: توكن | D23: نفس المصدر
A24: استخدام العميل في الشهر (افتراضات — مش أسعار)
A25: عدد عمليات البحث — Pro عادي | B25: 20 | C25: بحث | D25: افتراض
A26: رسائل Yolias AI — Pro عادي | B26: 100 | C26: رسالة | D26: افتراض
A27: إيميلات ورسايل تواصل مكتوبة — Pro عادي | B27: 200 | C27: رسالة | D27: افتراض
A28: استخدام Growth = استخدام Pro × | B28: 2 | C28: ضعف | D28: افتراض
A29: أقصى استخدام = الاستخدام العادي × | B29: 5 | C29: ضعف | D29: افتراض لأسوأ حالة
A30: العملاء المحتملين والبيانات
A31: عدد العملاء المحتملين — Pro | B31: 1000 | C31: Prospect / شهر | D31: قرارك (الرقم ده مثال من محادثتك، غيّره)
A32: عدد العملاء المحتملين — Growth | B32: 2500 | C32: Prospect / شهر | D32: قرارك (الرقم ده مثال من محادثتك، غيّره)
A33: تكلفة المزود لكل Prospect (سيناريو «مع المزود») | B33: 0.01 | C33: $ / Prospect | D33: مثال بس، مش سعر حقيقي. حط سعر المزود اللي هتختاره. سيناريو «قبل المزود» دايماً = 0
A34: قراءة الموقع (إيميل عام، تليفون، سوشيال) | B34: 0 | C34: $ / Prospect | D34: 0: طلب HTTP جوه حصة Cloudflare Workers (lib/intel/socials.ts)
A35: التحقق من الإيميل | B35: 0 | C35: $ / Prospect | D35: مفيش مزود تحقق مربوط. حط سعره لما يتربط
A36: تكلفة صانع القرار الواحد | B36: 0 | C36: $ / شخص | D36: مفيش مصدر لصنّاع القرار. حط سعره لما يتربط
A37: صنّاع القرار في الشهر — Pro | B37: 0 | C37: شخص | D37: قرارك بعد ربط المصدر
A38: صنّاع القرار في الشهر — Growth | B38: 0 | C38: شخص | D38: قرارك بعد ربط المصدر
A39: البنية التحتية — شهرياً
A40: Cloudflare Workers Paid | B40: 5 | C40: $ / شهر | D40: منك (مدفوع). فيه 10 مليون طلب في الشهر
...

Sheet تكلفة AI
A1: تكلفة الذكاء الاصطناعي لكل عملية ولكل عميل
A3: العملية | B3: Input (توكن) | C3: Output (توكن) | D3: التكلفة بالسعر الحالي | E3: التكلفة بسعر 2027 | F3: التكلفة المستخدمة
A4: تحليل طلب البحث (مرة لكل بحث) | B4: ='المدخلات'!$B$18 | C4: ='المدخلات'!$B$19 | D4: =B4*'المدخلات'!$B$12/1000000+C4*'المدخلات'!$B$13/1000000 | E4: =B4*'المدخلات'!$B$14/1000000+C4*'المدخلات'!$B$15/1000000 | F4: =IF('المدخلات'!$B$16=2,E4,D4)
A5: رسالة في Yolias AI | B5: ='المدخلات'!$B$20 | C5: ='المدخلات'!$B$21 | D5: =B5*'المدخلات'!$B$12/1000000+C5*'المدخلات'!$B$13/1000000 | E5: =B5*'المدخلات'!$B$14/1000000+C5*'المدخلات'!$B$15/1000000 | F5: =IF('المدخلات'!$B$16=2,E5,D5)
A6: كتابة إيميل / رسالة تواصل | B6: ='المدخلات'!$B$22 | C6: ='المدخلات'!$B$23 | D6: =B6*'المدخلات'!$B$12/1000000+C6*'المدخلات'!$B$13/1000000 | E6: =B6*'المدخلات'!$B$14/1000000+C6*'المدخلات'!$B$15/1000000 | F6: =IF('المدخلات'!$B$16=2,E6,D6)
A7: تقييم العميل المحتمل (Match) وتصنيفه: كود عادي، مش AI → التكلفة 0$
A9: تكلفة AI للعميل في الشهر | B9: عمليات بحث | C9: رسائل AI | D9: رسايل مكتوبة | E9: بالسعر الحالي | F9: بسعر 2027 | G9: المستخدمة
A10: Pro — استخدام عادي | B10: ='المدخلات'!$B$25*1 | C10: ='المدخلات'!$B$26*1 | D10: ='المدخلات'!$B$27*1 | E10: =B10*$D$4+C10*$D$5+D10*$D$6 | F10: =B10*$E$4+C10*$E$5+D10*$E$6 | G10: =IF('المدخلات'!$B$16=2,F10,E10)
A11: Pro — أقصى استخدام | B11: ='المدخلات'!$B$25*'المدخلات'!$B$29 | C11: ='المدخلات'!$B$26*'المدخلات'!$B$29 | D11: ='المدخلات'!$B$27*'المدخلات'!$B$29 | E11: =B11*$D$4+C11*$D$5+D11*$D$6 | F11: =B11*$E$4+C11*$E$5+D11*$E$6 | G11: =IF('المدخلات'!$B$16=2,F11,E11)
A12: Growth — استخدام عادي | B12: ='المدخلات'!$B$25*'المدخلات'!$B$28 | C12: ='المدخلات'!$B$26*'المدخلات'!$B$28 | D12: ='المدخلات'!$B$27*'المدخلات'!$B$28 | E12: =B12*$D$4+C12*$D$5+D12*$D$6 | F12: =B12*$E$4+C12*$E$5+D12*$E$6 | G12: =IF('المدخلات'!$B$16=2,F12,E12)
A13: Growth — أقصى استخدام | B13: ='المدخلات'!$B$25*'المدخلات'!$B$28*'المدخلات'!$B$29 | C13: ='المدخلات'!$B$26*'المدخلات'!$B$28*'المدخلات'!$B$29 | D13: ='المدخلات'!$B$27*'المدخلات'!$B$28*'المدخلات'!$B$29 | E13: =B13*$D$4+C13*$D$5+D13*$D$6 | F13: =B13*$E$4+C13*$E$5+D13*$E$6 | G13: =IF('المدخلات'!$B$16=2,F13,E13)
A15: التكلفة المستخدمة في باقي الشيت = حسب اختيار الأسعار في المدخلات

Sheet التكلفة الثابتة
A1: تكلفة يولياس الشهرية حسب عدد العملاء
A3: البند | B3: 10 عملاء | C3: 50 عميل | D3: 100 عميل | E3: 500 عميل | F3: 1,000 عميل
A4: عدد العملاء المدفوعين | B4: 10 | C4: 50 | D4: 100 | E4: 500 | F4: 1000
A5: التكاليف الثابتة
A6: Cloudflare Workers — الاشتراك | B6: ='المدخلات'!$B$40 | C6: ='المدخلات'!$B$40 | D6: ='المدخلات'!$B$40 | E6: ='المدخلات'!$B$40 | F6: ='المدخلات'!$B$40
A7: Cloudflare Workers — طلبات زيادة | B7: =MAX(0,B4*'المدخلات'!$B$58+'المدخلات'!$B$59-'المدخلات'!$B$60)/1000000*'المدخلات'!$B$61 | C7: =MAX(0,C4*'المدخلات'!$B$58+'المدخلات'!$B$59-'المدخلات'!$B$60)/1000000*'المدخلات'!$B$61 | D7: =MAX(0,D4*'المدخلات'!$B$58+'المدخلات'!$B$59-'المدخلات'!$B$60)/1000000*'المدخلات'!$B$61 | E7: =MAX(0,E4*'المدخلات'!$B$58+'المدخلات'!$B$59-'المدخلات'!$B$60)/1000000*'المدخلات'!$B$61 | F7: =MAX(0,F4*'المدخلات'!$B$58+'المدخلات'!$B$59-'المدخلات'!$B$60)/1000000*'المدخلات'!$B$61
A8: Supabase | B8: =IF('المدخلات'!$B$49=1,'المدخلات'!$B$42,'المدخلات'!$B$41) | C8: =IF('المدخلات'!$B$49=1,'المدخلات'!$B$42,'المدخلات'!$B$41) | D8: =IF('المدخلات'!$B$49=1,'المدخلات'!$B$42,'المدخلات'!$B$41) | E8: =IF('المدخلات'!$B$49=1,'المدخلات'!$B$42,'المدخلات'!$B$41) | F8: =IF('المدخلات'!$B$49=1,'المدخلات'!$B$42,'المدخلات'!$B$41)
A9: Resend | B9: =IF('المدخلات'!$B$49=1,'المدخلات'!$B$44,'المدخلات'!$B$43) | C9: =IF('المدخلات'!$B$49=1,'المدخلات'!$B$44,'المدخلات'!$B$43) | D9: =IF('المدخلات'!$B$49=1,'المدخلات'!$B$44,'المدخلات'!$B$43) | E9: =IF('المدخلات'!$B$49=1,'المدخلات'!$B$44,'المدخلات'!$B$43) | F9: =IF('المدخلات'!$B$49=1,'المدخلات'!$B$44,'المدخلات'!$B$43)
A10: PostHog | B10: ='المدخلات'!$B$45 | C10: ='المدخلات'!$B$45 | D10: ='المدخلات'!$B$45 | E10: ='المدخلات'!$B$45 | F10: ='المدخلات'!$B$45
A11: Sentry | B11: ='المدخلات'!$B$46 | C11: ='المدخلات'!$B$46 | D11: ='المدخلات'!$B$46 | E11: ='المدخلات'!$B$46 | F11: ='المدخلات'!$B$46
A12: Gemini (مفيش اشتراك ثابت) | B12: ='المدخلات'!$B$47 | C12: ='المدخلات'!$B$47 | D12: ='المدخلات'!$B$47 | E12: ='المدخلات'!$B$47 | F12: ='المدخلات'!$B$47
A13: الدومين (السنوي ÷ 12) | B13: ='المدخلات'!$B$48/12 | C13: ='المدخلات'!$B$48/12 | D13: ='المدخلات'!$B$48/12 | E13: ='المدخلات'!$B$48/12 | F13: ='المدخلات'!$B$48/12
A14: إجمالي التكلفة الثابتة في الشهر | B14: =SUM(B6:B13) | C14: =SUM(C6:C13) | D14: =SUM(D6:D13) | E14: =SUM(E6:E13) | F14: =SUM(F6:F13)
A16: هل الخطط المجانية كفاية؟
A17: إيميلات في الشهر | B17: =B4*'المدخلات'!$B$52 | C17: =C4*'المدخلات'!$B$52 | D17: =D4*'المدخلات'!$B$52 | E17: =E4*'المدخلات'!$B$52 | F17: =F4*'المدخلات'!$B$52
A18: إيميلات في اليوم (متوسط) | B18: =B17/30 | C18: =C17/30 | D18: =D17/30 | E18: =E17/30 | F18: =F17/30
A19: Resend | B19: =IF('المدخلات'!$B$49=1,IF(B17<='المدخلات'!$B$55,"Pro كفاية","محتاج خطة أعلى"),IF(AND(B17<='المدخلات'!$B$53,B18<='المدخلات'!$B$54),"المجاني كفاية","لازم ترقية")) | C19: =IF('المدخلات'!$B$49=1,IF(C17<='المدخلات'!$B$55,"Pro كفاية","محتاج خطة أعلى"),IF(AND(C17<='المدخلات'!$B$53,C18<='المدخلات'!$B$54),"المجاني كفاية","لازم ترقية")) | D19: =IF('المدخلات'!$B$49=1,IF(D17<='المدخلات'!$B$55,"Pro كفاية","محتاج خطة أعلى"),IF(AND(D17<='المدخلات'!$B$53,D18<='المدخلات'!$B$54),"المجاني كفاية","لازم ترقية")) | E19: =IF('المدخلات'!$B$49=1,IF(E17<='المدخلات'!$B$55,"Pro كفاية","محتاج خطة أعلى"),IF(AND(E17<='المدخلات'!$B$53,E18<='المدخلات'!$B$54),"المجاني كفاية","لازم ترقية")) | F19: =IF('المدخلات'!$B$49=1,IF(F17<='المدخلات'!$B$55,"Pro كفاية","محتاج خطة أعلى"),IF(AND(F17<='المدخلات'!$B$53,F18<='المدخلات'!$B$54),"المجاني كفاية","لازم ترقية"))
A20: أحداث PostHog في الشهر | B20: =B4*'المدخلات'!$B$56 | C20: =C4*'المدخلات'!$B$56 | D20: =D4*'المدخلات'!$B$56 | E20: =E4*'المدخلات'!$B$56 | F20: =F4*'المدخلات'!$B$56
A21: PostHog | B21: =IF(B20<='المدخلات'!$B$57,"المجاني كفاية","هيبدأ يتحاسب") | C21: =IF(C20<='المدخلات'!$B$57,"المجاني كفاية","هيبدأ يتحاسب") | D21: =IF(D20<='المدخلات'!$B$57,"المجاني كفاية","هيبدأ يتحاسب") | E21: =IF(E20<='المدخلات'!$B$57,"المجاني كفاية","هيبدأ يتحاسب") | F21: =IF(F20<='المدخلات'!$B$57,"المجاني كفاية","هيبدأ يتحاسب")
A23: الإيرادات والربح الشهري (استخدام عادي)
A24: عملاء Pro | B24: =ROUND(B4*'المدخلات'!$B$62,0) | C24: =ROUND(C4*'المدخلات'!$B$62,0) | D24: =ROUND(D4*'المدخلات'!$B$62,0) | E24: =ROUND(E4*'المدخلات'!$B$62,0) | F24: =ROUND(F4*'المدخلات'!$B$62,0)
A25: عملاء Growth | B25: =B4-B24 | C25: =C4-C24 | D25: =D4-D24 | E25: =E4-E24 | F25: =F4-F24
A26: الإيرادات | B26: =B24*'المدخلات'!$B$5+B25*'المدخلات'!$B$6 | C26: =C24*'المدخلات'!$B$5+C25*'المدخلات'!$B$6 | D26: =D24*'المدخلات'!$B$5+D25*'المدخلات'!$B$6 | E26: =E24*'المدخلات'!$B$5+E25*'المدخلات'!$B$6 | F26: =F24*'المدخلات'!$B$5+F25*'المدخلات'!$B$6
A27: رسوم Paymob | B27: =(B26*'المدخلات'!$B$8+B4*'المدخلات'!$B$9)*(1+'المدخلات'!$B$10) | C27: =(C26*'المدخلات'!$B$8+C4*'المدخلات'!$B$9)*(1+'المدخلات'!$B$10) | D27: =(D26*'المدخلات'!$B$8+D4*'المدخلات'!$B$9)*(1+'المدخلات'!$B$10) | E27: =(E26*'المدخلات'!$B$8+E4*'المدخلات'!$B$9)*(1+'المدخلات'!$B$10) | F27: =(F26*'المدخلات'!$B$8+F4*'المدخلات'!$B$9)*(1+'المدخلات'!$B$10)
A28: تكلفة AI | B28: =B24*'تكلفة AI'!$G$10+B25*'تكلفة AI'!$G$12 | C28: =C24*'تكلفة AI'!$G$10+C25*'تكلفة AI'!$G$12 | D28: =D24*'تكلفة AI'!$G$10+D25*'تكلفة AI'!$G$12 | E28: =E24*'تكلفة AI'!$G$10+E25*'تكلفة AI'!$G$12 | F28: =F24*'تكلفة AI'!$G$10+F25*'تكلفة AI'!$G$12
A29: التكلفة الثابتة | B29: =B14 | C29: =C14 | D29: =D14 | E29: =E14 | F29: =F14
A30: تكلفة البيانات — قبل المزود | B30: =B24*('المدخلات'!$B$31*('المدخلات'!$B$34+'المدخلات'!$B$35)+'المدخلات'!$B$37*'المدخلات'!$B$36)+B25*('المدخلات'!$B$32*('المدخلات'!$B$34+'المدخلات'!$B$35)+'المدخلات'!$B$38*'المدخلات'!$B$36) | C30: =C24*('المدخلات'!$B$31*('المدخلات'!$B$34+'المدخلات'!$B$35)+'المدخلات'!$B$37*'المدخلات'!$B$36)+C25*('المدخلات'!$B$32*('المدخلات'!$B$34+'المدخلات'!$B$35)+'المدخلات'!$B$38*'المدخلات'!$B$36) | D30: =D24*('المدخلات'!$B$31*('المدخلات'!$B$34+'المدخلات'!$B$35)+'المدخلات'!$B$37*'المدخلات'!$B$36)+D25*('المدخلات'!$B$32*('المدخلات'!$B$34+'المدخلات'!$B$35)+'المدخلات'!$B$38*'المدخلات'!$B$36) | E30: =E24*('المدخلات'!$B$31*('المدخلات'!$B$34+'المدخلات'!$B$35)+'المدخلات'!$B$37*'المدخلات'!$B$36)+E25*('المدخلات'!$B$32*('المدخلات'!$B$34+'المدخلات'!$B$35)+'المدخلات'!$B$38*'المدخلات'!$B$36) | F30: =F24*('المدخلات'!$B$31*('المدخلات'!$B$34+'المدخلات'!$B$35)+'المدخلات'!$B$37*'المدخلات'!$B$36)+F25*('المدخلات'!$B$32*('المدخلات'!$B$34+'المدخلات'!$B$35)+'المدخلات'!$B$38*'المدخلات'!$B$36)
A31: تكلفة البيانات — مع المزود | B31: =B30+(B24*'المدخلات'!$B$31+B25*'المدخلات'!$B$32)*'المدخلات'!$B$33 | C31: =C30+(C24*'المدخلات'!$B$31+C25*'المدخلات'!$B$32)*'المدخلات'!$B$33 | D31: =D30+(D24*'المدخلات'!$B$31+D25*'المدخلات'!$B$32)*'المدخلات'!$B$33 | E31: =E30+(E24*'المدخلات'!$B$31+E25*'المدخلات'!$B$32)*'المدخلات'!$B$33 | F31: =F30+(F24*'المدخلات'!$B$31+F25*'المدخلات'!$B$32)*'المدخلات'!$B$33
A32: إجمالي الربح — قبل المزود | B32: =B26-B27-B28-B29-B30 | C32: =C26-C27-C28-C29-C30 | D32: =D26-D27-D28-D29-D30 | E32: =E26-E27-E28-E29-E30 | F32: =F26-F27-F28-F29-F30
A33: هامش الربح — قبل المزود | B33: =IF(B26=0,0,B32/B26) | C33: =IF(C26=0,0,C32/C26) | D33: =IF(D26=0,0,D32/D26) | E33: =IF(E26=0,0,E32/E26) | F33: =IF(F26=0,0,F32/F26)
A34: إجمالي الربح — مع المزود | B34: =B26-B27-B28-B29-B31 | C34: =C26-C27-C28-C29-C31 | D34: =D26-D27-D28-D29-D31 | E34: =E26-E27-E28-E29-E31 | F34: =F26-F27-F28-F29-F31
A35: هامش الربح — مع المزود | B35: =IF(B26=0,0,B34/B26) | C35: =IF(C26=0,0,C34/C26) | D35: =IF(D26=0,0,D34/D26) | E35: =IF(E26=0,0,E34/E26) | F35: =IF(F26=0,0,F34/F26)
A37: ثابت: Workers، و Supabase، و Resend، و PostHog، و Sentry، والدومين. متغيّر مع الاستخدام: Paymob، و Gemini، والمزود، والتحقق، وصنّاع القرار، وطلبات Workers الزيادة.
A39: التكلفة الثابتة المستخدمة في توزيع نصيب العميل | B39: ='المدخلات'!$B$40+IF('المدخلات'!$B$49=1,'المدخلات'!$B$42+'المدخلات'!$B$44,'المدخلات'!$B$41+'المدخلات'!$B$43)+'المدخلات'!$B$45+'المدخلات'!$B$46+'المدخلات'!$B$47+'المدخلات'!$B$48/12
A40: نصيب العميل الواحد في الشهر | B40: =IF('المدخلات'!$B$50=0,0,B39/'المدخلات'!$B$50)

Sheet اقتصاديات الباقة
A1: ربح العميل الواحد في الشهر — قبل المزود ومع المزود
A3: 1) استخدام عادي
B4: Pro — قبل المزود | C4: Pro — مع المزود | D4: Growth — قبل المزود | E4: Growth — مع المزود
A5: الإيراد | B5: ='المدخلات'!$B$5 | C5: ='المدخلات'!$B$5 | D5: ='المدخلات'!$B$6 | E5: ='المدخلات'!$B$6
A6: عدد العملاء المحتملين | B6: ='المدخلات'!$B$31 | C6: ='المدخلات'!$B$31 | D6: ='المدخلات'!$B$32 | E6: ='المدخلات'!$B$32
A7: رسوم Paymob | B7: =(B5*'المدخلات'!$B$8+'المدخلات'!$B$9)*(1+'المدخلات'!$B$10) | C7: =(C5*'المدخلات'!$B$8+'المدخلات'!$B$9)*(1+'المدخلات'!$B$10) | D7: =(D5*'المدخلات'!$B$8+'المدخلات'!$B$9)*(1+'المدخلات'!$B$10) | E7: =(E5*'المدخلات'!$B$8+'المدخلات'!$B$9)*(1+'المدخلات'!$B$10)
A8: تكلفة AI | B8: ='تكلفة AI'!$G$10 | C8: ='تكلفة AI'!$G$10 | D8: ='تكلفة AI'!$G$12 | E8: ='تكلفة AI'!$G$12
A9: نصيب البنية التحتية | B9: ='التكلفة الثابتة'!$B$40 | C9: ='التكلفة الثابتة'!$B$40 | D9: ='التكلفة الثابتة'!$B$40 | E9: ='التكلفة الثابتة'!$B$40
A10: تكلفة المزود | B10: 0 | C10: =C6*'المدخلات'!$B$33 | D10: 0 | E10: =E6*'المدخلات'!$B$33
A11: قراءة الموقع + التحقق | B11: =B6*('المدخلات'!$B$34+'المدخلات'!$B$35) | C11: =C6*('المدخلات'!$B$34+'المدخلات'!$B$35) | D11: =D6*('المدخلات'!$B$34+'المدخلات'!$B$35) | E11: =E6*('المدخلات'!$B$34+'المدخلات'!$B$35)
A12: صنّاع القرار | B12: ='المدخلات'!$B$37*'المدخلات'!$B$36 | C12: ='المدخلات'!$B$37*'المدخلات'!$B$36 | D12: ='المدخلات'!$B$38*'المدخلات'!$B$36 | E12: ='المدخلات'!$B$38*'المدخلات'!$B$36
A13: إجمالي التكلفة | B13: =SUM(B7:B12) | C13: =SUM(C7:C12) | D13: =SUM(D7:D12) | E13: =SUM(E7:E12)
A14: إجمالي الربح | B14: =B5-B13 | C14: =C5-C13 | D14: =D5-D13 | E14: =E5-E13
A15: هامش الربح | B15: =IF(B5=0,0,B14/B5) | C15: =IF(C5=0,0,C14/C5) | D15: =IF(D5=0,0,D14/D5) | E15: =IF(E5=0,0,E14/E5)
A18: 2) أقصى استخدام (العميل بيخلّص كل العملاء المحتملين ويستخدم AI أكتر بكتير)
B19: Pro — قبل المزود | C19: Pro — مع المزود | D19: Growth — قبل المزود | E19: Growth — مع المزود
A20: الإيراد | B20: ='المدخلات'!$B$5 | C20: ='المدخلات'!$B$5 | D20: ='المدخلات'!$B$6 | E20: ='المدخلات'!$B$6
A21: عدد العملاء المحتملين | B21: ='المدخلات'!$B$31 | C21: ='المدخلات'!$B$31 | D21: ='المدخلات'!$B$32 | E21: ='المدخلات'!$B$32
A22: رسوم Paymob | B22: =(B20*'المدخلات'!$B$8+'المدخلات'!$B$9)*(1+'المدخلات'!$B$10) | C22: =(C20*'المدخلات'!$B$8+'المدخلات'!$B$9)*(1+'المدخلات'!$B$10) | D22: =(D20*'المدخلات'!$B$8+'المدخلات'!$B$9)*(1+'المدخلات'!$B$10) | E22: =(E20*'المدخلات'!$B$8+'المدخلات'!$B$9)*(1+'المدخلات'!$B$10)
A23: تكلفة AI | B23: ='تكلفة AI'!$G$11 | C23: ='تكلفة AI'!$G$11 | D23: ='تكلفة AI'!$G$13 | E23: ='تكلفة AI'!$G$13
A24: نصيب البنية التحتية | B24: ='التكلفة الثابتة'!$B$40 | C24: ='التكلفة الثابتة'!$B$40 | D24: ='التكلفة الثابتة'!$B$40 | E24: ='التكلفة الثابتة'!$B$40
A25: تكلفة المزود | B25: 0 | C25: =C21*'المدخلات'!$B$33 | D25: 0 | E25: =E21*'المدخلات'!$B$33
A26: قراءة الموقع + التحقق | B26: =B21*('المدخلات'!$B$34+'المدخلات'!$B$35) | C26: =C21*('المدخلات'!$B$34+'المدخلات'!$B$35) | D26: =D21*('المدخلات'!$B$34+'المدخلات'!$B$35) | E26: =E21*('المدخلات'!$B$34+'المدخلات'!$B$35)
A27: صنّاع القرار | B27: ='المدخلات'!$B$37*'المدخلات'!$B$36 | C27: ='المدخلات'!$B$37*'المدخلات'!$B$36 | D27: ='المدخلات'!$B$38*'المدخلات'!$B$36 | E27: ='المدخلات'!$B$38*'المدخلات'!$B$36
A28: إجمالي التكلفة | B28: =SUM(B22:B27) | C28: =SUM(C22:C27) | D28: =SUM(D22:D27) | E28: =SUM(E22:E27)
A29: إجمالي الربح | B29: =B20-B28 | C29: =C20-C28 | D29: =D20-D28 | E29: =E20-E28
A30: هامش الربح | B30: =IF(B20=0,0,B29/B20) | C30: =IF(C20=0,0,C29/C20) | D30: =IF(D20=0,0,D29/D20) | E30: =IF(E20=0,0,E29/E20)
A33: 3) أسوأ حالة: أقصى استخدام + أسعار Gemini بتاعة 2027
B34: Pro — قبل المزود | C34: Pro — مع المزود | D34: Growth — قبل المزود | E34: Growth — مع المزود
A35: الإيراد | B35: ='المدخلات'!$B$5 | C35: ='المدخلات'!$B$5 | D35: ='المدخلات'!$B$6 | E35: ='المدخلات'!$B$6
A36: عدد العملاء المحتملين | B36: ='المدخلات'!$B$31 | C36: ='المدخلات'!$B$31 | D36: ='المدخلات'!$B$32 | E36: ='المدخلات'!$B$32
A37: رسوم Paymob | B37: =(B35*'المدخلات'!$B$8+'المدخلات'!$B$9)*(1+'المدخلات'!$B$10) | C37: =(C35*'المدخلات'!$B$8+'المدخلات'!$B$9)*(1+'المدخلات'!$B$10) | D37: =(D35*'المدخلات'!$B$8+'المدخلات'!$B$9)*(1+'المدخلات'!$B$10) | E37: =(E35*'المدخلات'!$B$8+'المدخلات'!$B$9)*(1+'المدخلات'!$B$10)
A38: تكلفة AI | B38: ='تكلفة AI'!$F$11 | C38: ='تكلفة AI'!$F$11 | D38: ='تكلفة AI'!$F$13 | E38: ='تكلفة AI'!$F$13
A39: نصيب البنية التحتية | B39: ='التكلفة الثابتة'!$B$40 | C39: ='التكلفة الثابتة'!$B$40 | D39: ='التكلفة الثابتة'!$B$40 | E39: ='التكلفة الثابتة'!$B$40
A40: تكلفة المزود | B40: 0 | C40: =C36*'المدخلات'!$B$33 | D40: 0 | E40: =E36*'المدخلات'!$B$33
A41: قراءة الموقع + التحقق | B41: =B36*('المدخلات'!$B$34+'المدخلات'!$B$35) | C41: =C36*('المدخلات'!$B$34+'المدخلات'!$B$35) | D41: =D36*('المدخلات'!$B$34+'المدخلات'!$B$35) | E41: =E36*('المدخلات'!$B$34+'المدخلات'!$B$35)
A42: صنّاع القرار | B42: ='المدخلات'!$B$37*'المدخلات'!$B$36 | C42: ='المدخلات'!$B$37*'المدخلات'!$B$36 | D42: ='المدخلات'!$B$38*'المدخلات'!$B$36 | E42: ='المدخلات'!$B$38*'المدخلات'!$B$36
A43: إجمالي التكلفة | B43: =SUM(B37:B42) | C43: =SUM(C37:C42) | D43: =SUM(D37:D42) | E43: =SUM(E37:E42)
A44: إجمالي الربح | B44: =B35-B43 | C44: =C35-C43 | D44: =D35-D43 | E44: =E35-E43
A45: هامش الربح | B45: =IF(B35=0,0,B44/B35) | C45: =IF(C35=0,0,C44/C35) | D45: =IF(D35=0,0,D44/D35) | E45: =IF(E35=0,0,E44/E35)

Sheet لكل Prospect
A1: العميل المحتمل الواحد: بتبيعه بكام وبيكلفك كام (استخدام عادي)
B3: Pro — قبل المزود | C3: Pro — مع المزود | D3: Growth — قبل المزود | E3: Growth — مع المزود
A4: سعر بيع الـ Prospect | B4: =IF('اقتصاديات الباقة'!B6=0,0,'اقتصاديات الباقة'!B5/'اقتصاديات الباقة'!B6) | C4: =IF('اقتصاديات الباقة'!C6=0,0,'اقتصاديات الباقة'!C5/'اقتصاديات الباقة'!C6) | D4: =IF('اقتصاديات الباقة'!D6=0,0,'اقتصاديات الباقة'!D5/'اقتصاديات الباقة'!D6) | E4: =IF('اقتصاديات الباقة'!E6=0,0,'اقتصاديات الباقة'!E5/'اقتصاديات الباقة'!E6)
A5: رسوم Paymob | B5: =IF('اقتصاديات الباقة'!B6=0,0,'اقتصاديات الباقة'!B7/'اقتصاديات الباقة'!B6) | C5: =IF('اقتصاديات الباقة'!C6=0,0,'اقتصاديات الباقة'!C7/'اقتصاديات الباقة'!C6) | D5: =IF('اقتصاديات الباقة'!D6=0,0,'اقتصاديات الباقة'!D7/'اقتصاديات الباقة'!D6) | E5: =IF('اقتصاديات الباقة'!E6=0,0,'اقتصاديات الباقة'!E7/'اقتصاديات الباقة'!E6)
A6: AI | B6: =IF('اقتصاديات الباقة'!B6=0,0,'اقتصاديات الباقة'!B8/'اقتصاديات الباقة'!B6) | C6: =IF('اقتصاديات الباقة'!C6=0,0,'اقتصاديات الباقة'!C8/'اقتصاديات الباقة'!C6) | D6: =IF('اقتصاديات الباقة'!D6=0,0,'اقتصاديات الباقة'!D8/'اقتصاديات الباقة'!D6) | E6: =IF('اقتصاديات الباقة'!E6=0,0,'اقتصاديات الباقة'!E8/'اقتصاديات الباقة'!E6)
A7: البنية التحتية | B7: =IF('اقتصاديات الباقة'!B6=0,0,'اقتصاديات الباقة'!B9/'اقتصاديات الباقة'!B6) | C7: =IF('اقتصاديات الباقة'!C6=0,0,'اقتصاديات الباقة'!C9/'اقتصاديات الباقة'!C6) | D7: =IF('اقتصاديات الباقة'!D6=0,0,'اقتصاديات الباقة'!D9/'اقتصاديات الباقة'!D6) | E7: =IF('اقتصاديات الباقة'!E6=0,0,'اقتصاديات الباقة'!E9/'اقتصاديات الباقة'!E6)
A8: المزود | B8: =IF('اقتصاديات الباقة'!B6=0,0,'اقتصاديات الباقة'!B10/'اقتصاديات الباقة'!B6) | C8: =IF('اقتصاديات الباقة'!C6=0,0,'اقتصاديات الباقة'!C10/'اقتصاديات الباقة'!C6) | D8: =IF('اقتصاديات الباقة'!D6=0,0,'اقتصاديات الباقة'!D10/'اقتصاديات الباقة'!D6) | E8: =IF('اقتصاديات الباقة'!E6=0,0,'اقتصاديات الباقة'!E10/'اقتصاديات الباقة'!E6)
A9: قراءة الموقع + التحقق + صنّاع القرار | B9: =IF('اقتصاديات الباقة'!B6=0,0,('اقتصاديات الباقة'!B11+'اقتصاديات الباقة'!B12)/'اقتصاديات الباقة'!B6) | C9: =IF('اقتصاديات الباقة'!C6=0,0,('اقتصاديات الباقة'!C11+'اقتصاديات الباقة'!C12)/'اقتصاديات الباقة'!C6) | D9: =IF('اقتصاديات الباقة'!D6=0,0,('اقتصاديات الباقة'!D11+'اقتصاديات الباقة'!D12)/'اقتصاديات الباقة'!D6) | E9: =IF('اقتصاديات الباقة'!E6=0,0,('اقتصاديات الباقة'!E11+'اقتصاديات الباقة'!E12)/'اقتصاديات الباقة'!E6)
A10: تكلفة الـ Prospect الكاملة | B10: =SUM(B5:B9) | C10: =SUM(C5:C9) | D10: =SUM(D5:D9) | E10: =SUM(E5:E9)
A11: ربحك في الـ Prospect | B11: =B4-B10 | C11: =C4-C10 | D11: =D4-D10 | E11: =E4-E10
A12: الهامش | B12: =IF(B4=0,0,B11/B4) | C12: =IF(C4=0,0,C11/C4) | D12: =IF(D4=0,0,D11/D4) | E12: =IF(E4=0,0,E11/E4)
A14: «قبل المزود» = تكاليف التشغيل بس متوزعة على العملاء المحتملين. ملحوظة مهمة: من غير مزود مفيش عملاء محتملين بيتجمعوا أصلاً، فالعمود ده بيوضّح هيكل التكلفة، مش إيراد ممكن تحققه النهارده.

Sheet الهامش المستهدف
A1: قد إيه نقدر نصرف على البيانات عند كل هامش (استخدام عادي)
A3: Pro
A4: الهامش المستهدف | B4: أقصى تكلفة كلية | C4: تكلفة غير البيانات | D4: ميزانية البيانات للعميل | E4: أقصى سعر للـ Prospect (بعدد الباقة) | F4: أقصى عدد Prospects (بسعر المزود في المدخلات)
A5: 0.6 | B5: ='اقتصاديات الباقة'!B5*(1-A5) | C5: =('اقتصاديات الباقة'!B7+'اقتصاديات الباقة'!B8+'اقتصاديات الباقة'!B9+'اقتصاديات الباقة'!B11+'اقتصاديات الباقة'!B12) | D5: =MAX(0,B5-C5) | E5: =IF('اقتصاديات الباقة'!B6=0,0,D5/'اقتصاديات الباقة'!B6) | F5: =IF('المدخلات'!$B$33=0,"مش محدود بتكلفة البيانات",ROUNDDOWN(D5/'المدخلات'!$B$33,0))
A6: 0.7 | B6: ='اقتصاديات الباقة'!B5*(1-A6) | C6: =('اقتصاديات الباقة'!B7+'اقتصاديات الباقة'!B8+'اقتصاديات الباقة'!B9+'اقتصاديات الباقة'!B11+'اقتصاديات الباقة'!B12) | D6: =MAX(0,B6-C6) | E6: =IF('اقتصاديات الباقة'!B6=0,0,D6/'اقتصاديات الباقة'!B6) | F6: =IF('المدخلات'!$B$33=0,"مش محدود بتكلفة البيانات",ROUNDDOWN(D6/'المدخلات'!$B$33,0))
A7: 0.8 | B7: ='اقتصاديات الباقة'!B5*(1-A7) | C7: =('اقتصاديات الباقة'!B7+'اقتصاديات الباقة'!B8+'اقتصاديات الباقة'!B9+'اقتصاديات الباقة'!B11+'اقتصاديات الباقة'!B12) | D7: =MAX(0,B7-C7) | E7: =IF('اقتصاديات الباقة'!B6=0,0,D7/'اقتصاديات الباقة'!B6) | F7: =IF('المدخلات'!$B$33=0,"مش محدود بتكلفة البيانات",ROUNDDOWN(D7/'المدخلات'!$B$33,0))
A8: 0.9 | B8: ='اقتصاديات الباقة'!B5*(1-A8) | C8: =('اقتصاديات الباقة'!B7+'اقتصاديات الباقة'!B8+'اقتصاديات الباقة'!B9+'اقتصاديات الباقة'!B11+'اقتصاديات الباقة'!B12) | D8: =MAX(0,B8-C8) | E8: =IF('اقتصاديات الباقة'!B6=0,0,D8/'اقتصاديات الباقة'!B6) | F8: =IF('المدخلات'!$B$33=0,"مش محدود بتكلفة البيانات",ROUNDDOWN(D8/'المدخلات'!$B$33,0))
A11: Growth
A12: الهامش المستهدف | B12: أقصى تكلفة كلية | C12: تكلفة غير البيانات | D12: ميزانية البيانات للعميل | E12: أقصى سعر للـ Prospect (بعدد الباقة) | F12: أقصى عدد Prospects (بسعر المزود في المدخلات)
A13: 0.6 | B13: ='اقتصاديات الباقة'!D5*(1-A13) | C13: =('اقتصاديات الباقة'!D7+'اقتصاديات الباقة'!D8+'اقتصاديات الباقة'!D9+'اقتصاديات الباقة'!D11+'اقتصاديات الباقة'!D12) | D13: =MAX(0,B13-C13) | E13: =IF('اقتصاديات الباقة'!D6=0,0,D13/'اقتصاديات الباقة'!D6) | F13: =IF('المدخلات'!$B$33=0,"مش محدود بتكلفة البيانات",ROUNDDOWN(D13/'المدخلات'!$B$33,0))
A14: 0.7 | B14: ='اقتصاديات الباقة'!D5*(1-A14) | C14: =('اقتصاديات الباقة'!D7+'اقتصاديات الباقة'!D8+'اقتصاديات الباقة'!D9+'اقتصاديات الباقة'!D11+'اقتصاديات الباقة'!D12) | D14: =MAX(0,B14-C14) | E14: =IF('اقتصاديات الباقة'!D6=0,0,D14/'اقتصاديات الباقة'!D6) | F14: =IF('المدخلات'!$B$33=0,"مش محدود بتكلفة البيانات",ROUNDDOWN(D14/'المدخلات'!$B$33,0))
A15: 0.8 | B15: ='اقتصاديات الباقة'!D5*(1-A15) | C15: =('اقتصاديات الباقة'!D7+'اقتصاديات الباقة'!D8+'اقتصاديات الباقة'!D9+'اقتصاديات الباقة'!D11+'اقتصاديات الباقة'!D12) | D15: =MAX(0,B15-C15) | E15: =IF('اقتصاديات الباقة'!D6=0,0,D15/'اقتصاديات الباقة'!D6) | F15: =IF('المدخلات'!$B$33=0,"مش محدود بتكلفة البيانات",ROUNDDOWN(D15/'المدخلات'!$B$33,0))
A16: 0.9 | B16: ='اقتصاديات الباقة'!D5*(1-A16) | C16: =('اقتصاديات الباقة'!D7+'اقتصاديات الباقة'!D8+'اقتصاديات الباقة'!D9+'اقتصاديات الباقة'!D11+'اقتصاديات الباقة'!D12) | D16: =MAX(0,B16-C16) | E16: =IF('اقتصاديات الباقة'!D6=0,0,D16/'اقتصاديات الباقة'!D6) | F16: =IF('المدخلات'!$B$33=0,"مش محدود بتكلفة البيانات",ROUNDDOWN(D16/'المدخلات'!$B$33,0))
A18: طريقة القراءة: لو المزود هيكلّف أقل من العمود E، يبقى عدد العملاء المحتملين في الباقة محقق الهامش ده. العمود F بيقول أقصى عدد ينفع تديه بسعر المزود اللي في المدخلات.
